#VRML_SIM R2019a utf8
WorldInfo {
}
Viewpoint {
  orientation -0.08677667595802208 0.9912503671696553 0.09946113862056749 1.6525190493938196
  position 0.9371140660187783 0.4210366921622963 -0.16830404330954146
}
TexturedBackground {
}
TexturedBackgroundLight {
}
Floor {
}
Robot {
  translation 0 0.15 0
  children [
    Shape {
      appearance PBRAppearance {
        baseColor 0.5411764705882353 0.8862745098039215 0.20392156862745098
      }
      geometry Box {
        size 0.1 0.3 0.1
      }
    }
    HingeJoint {
      jointParameters HingeJointParameters {
        position 0.7853974999999995
        axis 0 1 0
        anchor 0 0.15 0
      }
      device [
        RotationalMotor {
          name "servo_motor"
          maxVelocity 13.1
          maxTorque 0.2157
        }
      ]
      endPoint Solid {
        translation 0 0.2 0
        rotation 0 -1 0 1.7680762758149537
        children [
          Shape {
            appearance PBRAppearance {
              baseColor 0.8 0 0
            }
            geometry DEF G_RED_BOX Box {
              size 0.1 0.1 0.1
            }
          }
        ]
        boundingObject USE G_RED_BOX
        physics Physics {
        }
        linearVelocity 0 -6.252799416968585e-16 0
        angularVelocity 0 4.440892098500626e-15 0
      }
    }
  ]
  controller "robot2"
}
