#VRML_SIM R2019a utf8
WorldInfo {
}
Viewpoint {
  orientation 0.020370034770937986 0.9997219461373728 -0.011878219341914333 1.4484702344803784
  position 1.7789675605263182 0.32641376927841137 0.2446348970593658
}
TexturedBackground {
}
TexturedBackgroundLight {
}
Floor {
}
Robot {
  translation 0 0.15 0
  children [
    Shape {
      appearance PBRAppearance {
        baseColor 0.5411764705882353 0.8862745098039215 0.20392156862745098
      }
      geometry Box {
        size 0.1 0.3 0.1
      }
    }
    DEF RED_BOX HingeJoint {
      jointParameters HingeJointParameters {
        axis 0 1 0
        anchor 0 0.2 0
      }
      device [
        RotationalMotor {
          name "servo_motor"
          maxVelocity 13.1
          maxTorque 0.2157
        }
      ]
      endPoint Solid {
        translation 0 0.2 0
        children [
          Shape {
            appearance PBRAppearance {
              baseColor 0.8 0 0
            }
            geometry DEF G_RED_BOX Box {
              size 0.1 0.1 0.1
            }
          }
          HingeJoint {
            jointParameters HingeJointParameters {
              anchor 0 0.05 0
            }
            device [
              RotationalMotor {
                name "servo_motor_2"
                maxVelocity 13.1
                maxTorque 0.216
              }
            ]
            endPoint Solid {
              translation 0 0.2 0
              rotation 1 0 0 0
              children [
                Shape {
                  appearance PBRAppearance {
                    baseColor 0.9294117647058824 0.8313725490196079 0
                  }
                  geometry DEF G_YELLOW_BOX Box {
                    size 0.1 0.3 0.1
                  }
                }
              ]
              name "solid(1)"
              boundingObject USE G_YELLOW_BOX
            }
          }
        ]
        boundingObject USE G_RED_BOX
        physics Physics {
        }
      }
    }
  ]
  controller "robot2"
}
